Workbook

Sheet Feuil1
A1: Fichier | B1: Enr | C1: EAA | D1: Début | E1: Fin | F1: Lever_Soleil_Moy | G1: Coucher_Soleil_Moy | H1: Longueur_Jour_Moy | I1: Latitude | J1: Longitude | K1: Alt | L1: Commune | M1: Sous_île | N1: Île | O1: Archipel | P1: Hab | Q1: Station_Prec | R1: Station_Temp | S1: P_J_Moy | T1: P_J_Max | U1: T_Min_M | V1: T_Max_M | W1: Azi | X1: Ori | Y1: Val | Z1: D_R_P | AA1: D_M | AB1: D_B | AC1: HSA | AD1: Surface batie (m) | AE1: Arb | AF1: Arbu | AG1: Her | AH1: Ant | AI1: N/E | AJ1: S | AK1: P/A_Myna | AL1: P/A_Natif | AM1: S_Exo | AN1: Tps_Ana | AO1: Nb_Day_2024 | AP1: Qualité,Commentaire
A2: Ifremer_1 SMM02747 - 2702_03032024 - Gaia -17.80597, -149.29421 - Carte SD 128 Go A15 extreme | B2: Ifremer_1 | C2: SMM02747 | D2: 45349 | E2: 45354 | F2: =AVERAGE(Soleil!$B$5:$B$10) -> 0.24780093 | G2: =AVERAGE(Soleil!$C$5:$C$10) -> 0.76435185 | H2: =AVERAGE(Soleil!$D$5:$D$10) -> 0.51631944 | I2: -17.80597 | J2: -149.29421 | K2: 5 | L2: Vairao | M2: Tahiti Iti | N2: Tahiti | O2: Société | P2: Suburbain | Q2: VAIRAO 1 | R2: VAIRAO 1 | S2: =AVERAGE(Précipitation!B5:B10) -> 2.7833333 | T2: =MAX(Précipitation!B5:B10) -> 9.5 | U2: =AVERAGE(Température!B5:B10) -> 24.633333 | V2: =AVERAGE(Température!C5:C10) -> 31.9 | W2: 271.4 | X2: O | Y2: Hors vallée | Z2: 112 | AA2: 46.7 | AB2: 10.9 | AC2: =(AD2/31416) -> 0.39477655 | AD2: =11098+63.3+63.4+230+912+23+12.6 -> 12402.3 | AE2: 0 | AF2: 0 | AG2: 40 | AH2: 60 | AI2: =Feuil2!J3/Feuil2!K3 -> 0 | AJ2: =Feuil2!J3+Feuil2!K3 -> 5 | AK2: =IF(COUNTIF(Feuil2!B3:B7,"Acridotheres tristis"),1,0) -> 1 | AL2: =IF(COUNTIF(Feuil2!C3:C7,"Natif"),1,0) -> 0 | AM2: =Feuil2!K3 -> 5 | AN2: 325 | AO2: 58
A3: Ifremer_2 SMM02940 - 2702_03032024 - Gaia -17.80483, -149.29361 - Carte SD 32 Go noire K | B3: Ifremer_2 | C3: SMM09240 | D3: 45349 | E3: 45354 | F3: =AVERAGE(Soleil!$B$5:$B$10) -> 0.24780093 | G3: =AVERAGE(Soleil!$C$5:$C$10) -> 0.76435185 | H3: =AVERAGE(Soleil!$D$5:$D$10) -> 0.51631944 | I3: -17.80483 | J3: -149.29361 | K3: 7 | L3: Vairao | M3: Tahiti Iti | N3: Tahiti | O3: Société | P3: Suburbain | Q3: VAIRAO 1 | R3: VAIRAO 1 | S3: =AVERAGE(Précipitation!B5:B10) -> 2.7833333 | T3: =MAX(Précipitation!B5:B10) -> 9.5 | U3: =AVERAGE(Température!B5:B10) -> 24.633333 | V3: =AVERAGE(Température!C5:C10) -> 31.9 | W3: 272.3 | X3: O | Y3: Hors vallée | Z3: 27.9 | AA3: 132 | AB3: 28.2 | AC3: =(AD3/31416) -> 0.34924561 | AD3: =10209+572+45.7+13.5+51+80.7 -> 10971.9 | AE3: 0 | AF3: 0 | AG3: 70 | AH3: 20 | AI3: =Feuil2!J53/Feuil2!K53 -> 0 | AJ3: =Feuil2!J53+Feuil2!K53 -> 5 | AK3: =IF(COUNTIF(Feuil2!B337:B341,"Acridotheres tristis"),1,0) -> 1 | AL3: =IF(COUNTIF(Feuil2!C337:C341,"Natif"),1,0) -> 0 | AM3: =Feuil2!K53 -> 5 | AN3: 340 | AO3: 58
A4: ILM_1 SMM09233 - 1204_170424 - Gaia -17.73177, -149.57868 | B4: ILM_1 | C4: SMM02747 | D4: 45394 | E4: 45399 | F4: =AVERAGE(Soleil!$E$5:$E$10) -> 0.25555556 | G4: =AVERAGE(Soleil!$F$5:$F$10) -> 0.7412037 | H4: =AVERAGE(Soleil!$G$5:$G$10) -> 0.48506944 | I4: -17.73177 | J4: -149.57868 | K4: 11 | L4: ILM_Paea | M4: Tahiti Nui | N4: Tahiti | O4: Société | P4: Suburbain | Q4: PAPARA 8, PAEA 3 | R4: PAPARA 8 | S4: =AVERAGE(Précipitation!C5:C10,Précipitation!C12:C17) -> 0.033333333 | T4: =MAX(Précipitation!C5:C10,Précipitation!C12:C17) -> 0.4 | U4: =AVERAGE(Température!D5:D10) -> 25.183333 | V4: =AVERAGE(Température!E5:E10) -> 30.316667 | W4: 231.2 | X4: SO | Y4: Hors vallée | Z4: 70 | AA4: 125 | AB4: 12.5 | AC4: =(AD4/31416) -> 0.31381143 | AD4: =2747+210+124+305+124+55.5+183+137+190+755+670+226+31.7+141+158+21.4+173+131+56.3+337+300+165+218+13.8+213+1663+179+127+204 -> 9858.7 | AE4: 20 | AF4: 10 | AG4: 60 | AH4: 40 | AI4: =Feuil2!J4/Feuil2!K4 -> 0 | AJ4: =Feuil2!J4+Feuil2!K4 -> 7 | AK4: =IF(COUNTIF(Feuil2!B8:B14,"Acridotheres tristis"),1,0) -> 1 | AL4: =IF(COUNTIF(Feuil2!C8:C14,"Natif"),1,0) -> 0 | AM4: =Feuil2!K4 -> 7 | AN4: 350 | AO4: 103
A5: ILM_2 SMM09080 - 1204_170424 - Gaia -17.73335, -149.57899 | B5: ILM_2 | C5: SMM09080 | D5: 45394 | E5: 45399 | F5: =AVERAGE(Soleil!$H$5:$H$10) -> 0.25555556 | G5: =AVERAGE(Soleil!$I$5:$I$10) -> 0.7412037 | H5: =AVERAGE(Soleil!$J$5:$J$10) -> 0.48506944 | I5: -17.73335 | J5: -149.57899 | K5: 4 | L5: ILM_Paea | M5: Tahiti Nui | N5: Tahiti | O5: Société | P5: Suburbain | Q5: PAPARA 8, PAEA 3 | R5: PAPARA 8 | S5: =AVERAGE(Précipitation!D5:D10,Précipitation!D12:D17) -> 0.033333333 | T5: =MAX(Précipitation!D5:D10,Précipitation!D12:D17) -> 0.4 | U5: =AVERAGE(Température!F5:F10) -> 25.183333 | V5: =AVERAGE(Température!G5:G10) -> 30.316667 | W5: 230.8 | X5: SO | Y5: Hors vallée | Z5: 59.2 | AA5: 3.74 | AB5: 26.3 | AC5: =(AD5/31416) -> 0.10314171 | AD5: =143+42+60.6+968+122+1672+62.7+170 -> 3240.3 | AE5: 10 | AF5: 0 | AG5: 80 | AH5: 20 | AI5: =Feuil2!J5/Feuil2!K5 -> 0 | AJ5: =Feuil2!J5+Feuil2!K5 -> 8 | AK5: =IF(COUNTIF(Feuil2!B15:B22,"Acridotheres tristis"),1,0) -> 1 | AL5: =IF(COUNTIF(Feuil2!C15:C22,"Natif"),1,0) -> 0 | AM5: =Feuil2!K5 -> 8 | AN5: 360 | AO5: 103
A6: ILM_3 SMM09037 - 1204_170424 - Gaia -17.73234, -149.57782 | B6: ILM_3 | C6: SMM09285 | D6: 45394 | E6: 45399 | F6: =AVERAGE(Soleil!$K$5:$K$10) -> 0.25555556 | G6: =AVERAGE(Soleil!$L$5:$L$10) -> 0.7412037 | H6: =AVERAGE(Soleil!$M$5:$M$10) -> 0.48506944 | I6: -17.73234 | J6: -149.57782 | K6: 18 | L6: ILM_Paea | M6: Tahiti Nui | N6: Tahiti | O6: Société | P6: Suburbain | Q6: PAPARA 8, PAEA 3 | R6: PAPARA 8 | S6: =AVERAGE(Précipitation!E5:E10,Précipitation!E12:E17) -> 0.033333333 | T6: =MAX(Précipitation!E5:E10,Précipitation!E12:E17) -> 0.4 | U6: =AVERAGE(Température!H5:H10) -> 25.183333 | V6: =AVERAGE(Température!I5:I10) -> 30.316667 | W6: 230.9 | X6: SO | Y6: Hors vallée | Z6: 106 | AA6: 125 | AB6: 12.4 | AC6: =(AD6/31416) -> 0.14001114 | AD6: =300+45+12.4+2787+37+672+42.3+21.4+64.8+60.7+347+8.99 -> 4398.59 | AE6: 0 | AF6: 10 | AG6: 80 | AH6: 20 | AI6: =Feuil2!J6/Feuil2!K6 -> 0 | AJ6: =Feuil2!J6+Feuil2!K6 -> 6 | AK6: =IF(COUNTIF(Feuil2!B23:B28,"Acridotheres tristis"),1,0) -> 1 | AL6: =IF(COUNTIF(Feuil2!C23:C28,"Natif"),1,0) -> 0 | AM6: =Feuil2!K6 -> 6 | AN6: 330 | AO6: 103 | AP6: Criquet en bande passante lors des points écoute
A7: Jardin_Eau_1 SMM09285 - 2803_020424 - Gaia -17.76020, -149.38919 - Carte SD 32 Go noire (PB lecture carte) | B7: Jardin_Eau_1 | C7: SMM09285 | D7: 45379 | E7: 45384 | F7: =AVERAGE(Soleil!$N$5:$N$10) -> 0.25335648 | G7: =AVERAGE(Soleil!$O$5:$O$10) -> 0.74884259 | H7: =AVERAGE(Soleil!$P$5:$P$10) -> 0.49548611 | I7: -17.76020 | J7: -149.38919 | K7: 24 | L7: Mataiea | M7: Tahiti Nui | N7: Tahiti | O7: Société | P7: Forêt | Q7: PAPEARI 1, PAPEARI4, MATAIEA 4 | R7: PAPEARI 1 | S7: =AVERAGE(Précipitation!F5:F10,Précipitation!F12:F17,Précipitation!F19:F24) -> 3.9166667 | T7: =MAX(Précipitation!F5:F10,Précipitation!F12:F17,Précipitation!F19:F24) -> 24.6 | U7: =AVERAGE(Température!J5:J10) -> 24.25 | V7: =AVERAGE(Température!K5:K10) -> 31.266667 | W7: 155.5 | X7: SSE | Y7: Hors vallée | Z7: 45.2 | AA7: 62.5 | AB7: 71.4 | AC7: =(AD7/31416) -> 0.073007385 | AD7: =2165+102+26.6 -> 2293.6 | AE7: 50 | AF7: 30 | AG7: 60 | AH7: 20 | AI7: =Feuil2!J7/Feuil2!K7 -> 0.16666667 | AJ7: =Feuil2!J7+Feuil2!K7 -> 7 | AK7: =IF(COUNTIF(Feuil2!B29:B35,"Acridotheres tristis"),1,0) -> 1 | AL7: =IF(COUNTIF(Feuil2!C29:C35,"Natif"),1,0) -> 1 | AM7: =Feuil2!K7 -> 6 | AN7: 370 | AO7: 88
A8: Jardin_Eau_2 SMM02747 - 2803_02042024 - Gaia -17.75749, -149.39176 - Carte SD 32 Go J noire | B8: Jardin_Eau_2 | C8: SMM02747 | D8: 45379 | E8: 45384 | F8: =AVERAGE(Soleil!$Q$5:$Q$10) -> 0.25335648 | G8: =AVERAGE(Soleil!$R$5:$R$10) -> 0.74884259 | H8: =AVERAGE(Soleil!$S$5:$S$10) -> 0.49548611 | I8: -17.75749 | J8: -149.39176 | K8: 107 | L8: Mataiea | M8: Tahiti Nui | N8: Tahiti | O8: Société | P8: Forêt | Q8: PAPEARI 1, PAPEARI4, MATAIEA 4 | R8: PAPEARI 1 | S8: =AVERAGE(Précipitation!G5:G10,Précipitation!G12:G17,Précipitation!G19:G24) -> 3.9166667 | T8: =MAX(Précipitation!G5:G10,Précipitation!G12:G17,Précipitation!G19:G24) -> 24.6 | U8: =AVERAGE(Température!L5:L10) -> 24.25 | V8: =AVERAGE(Température!M5:M10) -> 31.266667 | W8: 155.9 | X8: SSE | Y8: Crête vallée | Z8: 414 | AA8: 468 | AB8: 372 | AC8: =(AD8/31416) -> 0 | AD8: 0 | AE8: 90 | AF8: 20 | AG8: 70 | AH8: 0 | AI8: =Feuil2!J8/Feuil2!K8 -> 0.14285714 | AJ8: =Feuil2!J8+Feuil2!K8 -> 8 | AK8: =IF(COUNTIF(Feuil2!B36:B43,"Acridotheres tristis"),1,0) -> 0 | AL8: =IF(COUNTIF(Feuil2!C36:C43,"Natif"),1,0) -> 1 | AM8: =Feuil2!K8 -> 7 | AN8: 370 | AO8: 88
A9: Jardin_Eau_3 SMM09009 - 2803_02042024 - Gaia -17.75383, -149.39297 - Carte SD 32 Go extreme | B9: Jardin_Eau_3 | C9: SMM09009 | D9: 45379 | E9: 45384 | F9: =AVERAGE(Soleil!$T$5:$T$10) -> 0.25335648 | G9: =AVERAGE(Soleil!$U$5:$U$10) -> 0.74884259 | H9: =AVERAGE(Soleil!$V$5:$V$10) -> 0.49548611 | I9: -17.75383 | J9: -149.39297 | K9: 191 | L9: Mataiea | M9: Tahiti Nui | N9: Tahiti | O9: Société | P9: Forêt | Q9: PAPEARI 1, PAPEARI4, MATAIEA 4 | R9: PAPEARI 1 | S9: =AVERAGE(Précipitation!H5:H10,Précipitation!H12:H17,Précipitation!H19:H24) -> 3.9166667 | T9: =MAX(Précipitation!H5:H10,Précipitation!H12:H17,Précipitation!H19:H24) -> 24.6 | U9: =AVERAGE(Température!N5:N10) -> 24.25 | V9: =AVERAGE(Température!O5:O10) -> 31.266667 | W9: 155.7 | X9: SSE | Y9: Crête vallée | Z9: 851 | AA9: 888 | AB9: 808 | AC9: =(AD9/31416) -> 0 | AD9: 0 | AE9: 90 | AF9: 60 | AG9: 20 | AH9: 0 | AI9: =Feuil2!J9/Feuil2!K9 -> 0 | AJ9: =Feuil2!J9+Feuil2!K9 -> 5 | AK9: =IF(COUNTIF(Feuil2!B44:B48,"Acridotheres tristis"),1,0) -> 1 | AL9: =IF(COUNTIF(Feuil2!C44:C48,"Natif"),1,0) -> 0 | AM9: =Feuil2!K9 -> 5 | AN9: 370 | AO9: 88
A10: Jardin_Eau_4 SMM09307 - 2803_02042024 - Gaia -17.74614, -149.39308 - Carte SD 64 Go E27 extreme | B10: Jardin_Eau_4 | C10: SMM09307 | D10: 45379 | E10: 45384 | F10: =AVERAGE(Soleil!$W$5:$W$10) -> 0.25335648 | G10: =AVERAGE(Soleil!$X$5:$X$10) -> 0.74884259 | H10: =AVERAGE(Soleil!$Y$5:$Y$10) -> 0.49548611 | I10: -17.749837 | J10: -149.393569 | K10: 235 | L10: Mataiea | M10: Tahiti Nui | N10: Tahiti | O10: Société | P10: Forêt | Q10: PAPEARI 1, PAPEARI4, MATAIEA 4 | R10: PAPEARI 1 | S10: =AVERAGE(Précipitation!I5:I10,Précipitation!I12:I17,Précipitation!I19:I24) -> 3.9166667 | T10: =MAX(Précipitation!I7:I12,Précipitation!I14:I19,Précipitation!I21:I26) -> 24.6 | U10: =AVERAGE(Température!P5:P10) -> 24.25 | V10: =AVERAGE(Température!Q5:Q10) -> 31.266667 | W10: 155.2 | X10: SSE | Y10: Crête vallée | Z10: 1289 | AA10: 1314 | AB10: 1096 | AC10: =(AD10/31416) -> 0 | AD10: 0 | AE10: 80 | AF10: 60 | AG10: 70 | AH10: 0 | AI10: =Feuil2!J10/Feuil2!K10 -> 0.2 | AJ10: =Feuil2!J10+Feuil2!K10 -> 6 | AK10: =IF(COUNTIF(Feuil2!B49:B54,"Acridotheres tristis"),1,0) -> 0 | AL10: =IF(COUNTIF(Feuil2!C49:C54,"Natif"),1,0) -> 1 | AM10: =Feuil2!K10 -> 5 | AN10: 370 | AO10: 88
A11: Jardin_Eau_5 SMM09037 - 2803_02042024 - Gaia -17.74614, -149.39308 - Carte SD 32 Go G samsung | B11: Jardin_Eau_5 | C11: SMM09037 | D11: 45379 | E11: 45384 | F11: =AVERAGE(Soleil!$Z$5:$Z$10) -> 0.25335648 | G11: =AVERAGE(Soleil!$AA$5:$AA$10) -> 0.74884259 | H11: =AVERAGE(Soleil!$AB$5:$AB$10) -> 0.49548611 | I11: -17.74614 | J11: -149.39308 | K11: 289 | L11: Mataiea | M11: Tahiti Nui | N11: Tahiti | O11: Société | P11: Forêt | Q11: PAPEARI 1, PAPEARI4, MATAIEA 4 | R11: PAPEARI 1 | S11: =AVERAGE(Précipitation!J5:J10,Précipitation!J12:J17,Précipitation!J19:J24) -> 3.9166667 | T11: =MAX(Précipitation!J5:J10,Précipitation!J12:J17,Précipitation!J19:J24) -> 24.6 | U11: =AVERAGE(Température!R5:R10) -> 24.25 | V11: =AVERAGE(Température!S5:S10) -> 31.266667 | W11: 154.3 | X11: SSE | Y11: Crête vallée | Z11: 1675 | AA11: 1691 | AB11: 1332 | AC11: =(AD11/31416) -> 0 | AD11: 0 | AE11: 90 | AF11: 70 | AG11: 30 | AH11: 0 | AI11: =Feuil2!J11/Feuil2!K11 -> 0 | AJ11: =Feuil2!J11+Feuil2!K11 -> 5 | AK11: =IF(COUNTIF(Feuil2!B55:B59,"Acridotheres tristis"),1,0) -> 0 | AL11: =IF(COUNTIF(Feuil2!C55:C59,"Natif"),1,0) -> 0 | AM11: =Feuil2!K11 -> 5 | AN11: 370 | AO11: 88
A12: Marae_1 SMM02755 - 1004_15042024 - Gaia -17.69697, -149.58110 | B12: Marae_1 | C12: SMM02755 | D12: 45392 | E12: 45397 | F12: =AVERAGE(Soleil!$AC$5:$AC$10) -> 0.25520833 | G12: =AVERAGE(Soleil!$AE$5:$AE$10) -> 0.48645833 | H12: =AVERAGE(Soleil!$AF$5:$AF$10) -> 0.25503472 | I12: -17.69697 | J12: -149.58110 | K12: 22 | L12: Paea | M12: Tahiti Nui | N12: Tahiti | O12: Société | P12: Suburbain | Q12: PAEA 3 | R12: PAPARA 8, PUNAAUIA 6 | S12: =AVERAGE(Précipitation!K5:K10) -> 0.33333333 | T12: =MAX(Précipitation!K5:K10) -> 2 | U12: =AVERAGE(Température!T5:T10,Température!T12:T17) -> 24.908333 | V12: =AVERAGE(Température!U5:U10,Température!U12:U17) -> 31.333333 | W12: 243 | X12: OSO | Y12: Hors vallée | Z12: 262 | AA12: 391 | AB12: 19.5 | AC12: =(AD12/31416) -> 0.30680863 | AD12: =840+116+388+24+121+296+309+226+93.7+808+139+381+198+206+178+5+45.3+157+171+529+333+475+1330+1284+687+106+168+24.7 -> 9638.7 | AE12: 10 | AF12: 0 | AG12: 10 | AH12: 90 | AI12: =Feuil2!J12/Feuil2!K12 -> 0 | AJ12: =Feuil2!J12+Feuil2!K12 -> 7 | AK12: =IF(COUNTIF(Feuil2!B60:B66,"Acridotheres tristis"),1,0) -> 1 | AL12: =IF(COUNTIF(Feuil2!C60:C66,"Natif"),1,0) -> 0 | AM12: =Feuil2!K12 -> 7 | AN12: 390 | AO12: 101
A13: Marae_2 SMM09307 - 1004_130424 - Gaia -17.69722, -149.57881 | B13: Marae_2 | C13: SMM09307 | D13: 45392 | E13: 45395 | F13: =AVERAGE(Soleil!$AF$5:$AF$8) -> 0.25503472 | G13: =AVERAGE(Soleil!$AG$5:$AG$8) -> 0.74270833 | H13: =AVERAGE(Soleil!$AH$5:$AH$10) -> 0.48715278 | I13: -17.69722 | J13: -149.57881 | K13: 45 | L13: Paea | M13: Tahiti Nui | N13: Tahiti | O13: Société | P13: Forêt | Q13: PAEA 3 | R13: PAPARA 8, PUNAAUIA 6 | S13: =AVERAGE(Précipitation!L5:L8) -> 0.5 | T13: =MAX(Précipitation!L5:L8) -> 2 | U13: =AVERAGE(Température!V5:V8,Température!V12:V15) -> 25.0375 | V13: =AVERAGE(Température!W5:W8,Température!W12:W15) -> 31.5625 | W13: 242.5 | X13: OSO | Y13: Fond vallée | Z13: 510 | AA13: 632 | AB13: 126 | AC13: =(AD13/31416) -> 0.011204482 | AD13: 352 | AE13: 40 | AF13: 20 | AG13: 70 | AH13: 0 | AI13: =Feuil2!J13/Feuil2!K13 -> 0.28571429 | AJ13: =Feuil2!J13+Feuil2!K13 -> 9 | AK13: =IF(COUNTIF(Feuil2!B67:B75,"Acridotheres tristis"),1,0) -> 1 | AL13: =IF(COUNTIF(Feuil2!C67:C75,"Natif"),1,0) -> 1 | AM13: =Feuil2!K13 -> 7 | AN13: 215 | AO13: 101
A14: Marae_3 SMM09106 - 1004_160424 - Gaia -17.69643, -149.57515 | B14: Marae_3 | C14: SMM09106 | D14: 45392 | E14: 45398 | F14: =AVERAGE(Soleil!$AI$5:$AI$10) -> 0.25520833 | G14: =AVERAGE(Soleil!$AJ$5:$AJ$10) -> 0.74224537 | H14: =AVERAGE(Soleil!$AK$5:$AK$10) -> 0.48645833 | I14: -17.69643 | J14: -149.57515 | K14: 93 | L14: Paea | M14: Tahiti Nui | N14: Tahiti | O14: Société | P14: Forêt | Q14: PAEA 3 | R14: PAPARA 8, PUNAAUIA 6 | S14: =AVERAGE(Précipitation!M5:M11) -> 0.28571429 | T14: =MAX(Précipitation!M5:M11) -> 2 | U14: =AVERAGE(Température!X5:X11,Température!X13:X19) -> 24.871429 | V14: =AVERAGE(Température!Y5:Y11,Température!Y13:Y19) -> 31.185714 | W14: 242.1 | X14: OSO | Y14: Fond vallée | Z14: 899 | AA14: 1026 | AB14: 408 | AC14: =(AD14/31416) -> 0 | AD14: 0 | AE14: 90 | AF14: 60 | AG14: 0 | AH14: 0 | AI14: =Feuil2!J14/Feuil2!K14 -> 0 | AJ14: =Feuil2!J14+Feuil2!K14 -> 4 | AK14: =IF(COUNTIF(Feuil2!B76:B79,"Acridotheres tristis"),1,0) -> 0 | AL14: =IF(COUNTIF(Feuil2!C76:C79,"Natif"),1,0) -> 0 | AM14: =Feuil2!K14 -> 4 | AN14: 390 | AO14: 101
A15: Marae_4 SMM02747 - 1004_130424 - Gaia -17.69581, -149.57105 | B15: Marae_4 | C15: SMM02747 | D15: 45392 | E15: 45395 | F15: =AVERAGE(Soleil!$AL$5:$AL$8) -> 0.25503472 | G15: =AVERAGE(Soleil!$AM$5:$AM$10) -> 0.74270833 | H15: =AVERAGE(Soleil!$AN$5:$AN$10) -> 0.48715278 | I15: -17.69581 | J15: -149.57105 | K15: 141 | L15: Paea | M15: Tahiti Nui | N15: Tahiti | O15: Société | P15: Forêt | Q15: PAEA 3 | R15: PAPARA 8, PUNAAUIA 6 | S15: =AVERAGE(Précipitation!N5:N8) -> 0.5 | T15: =MAX(Précipitation!N5:N8) -> 2 | U15: =AVERAGE(Température!Z5:Z8,Température!Z12:Z15) -> 25.0375 | V15: =AVERAGE(Température!AA5:AA8,Température!AA12:AA15) -> 31.5625 | W15: 241.5 | X15: OSO | Y15: Fond vallée | Z15: 1335 | AA15: 1460 | AB15: 835 | AC15: =(AD15/31416) -> 0.0012605042 | AD15: 39.6 | AE15: 90 | AF15: 40 | AG15: 40 | AH15: 0 | AI15: =Feuil2!J15/Feuil2!K15 -> 0 | AJ15: =Feuil2!J15+Feuil2!K15 -> 6 | AK15: =IF(COUNTIF(Feuil2!B80:B85,"Acridotheres tristis"),1,0) -> 1 | AL15: =IF(COUNTIF(Feuil2!C80:C85,"Natif"),1,0) -> 0 | AM15: =Feuil2!K15 -> 6 | AN15: 190 | AO15: 101
A16: OBelvedere_1 SMM02928 - 2703_01042024 - Gaia -17.57431, -149.52287 - Carte SD 128 Go A15 extreme (mouillé) | B16: OBelvedere_1 | C16: SMM02928 | D16: 45378 | E16: 45383 | F16: =AVERAGE(Soleil!$AO$5:$AO$10) -> 0.253125 | G16: =AVERAGE(Soleil!$AP$5:$AP$10) -> 0.7494213 | H16: =AVERAGE(Soleil!$AQ$5:$AQ$10) -> 0.49618056 | I16: -17.57431 | J16: -149.52287 | K16: 810 | L16: Pirae | M16: Tahiti Nui | N16: Tahiti | O16: Société | P16: Forêt | Q16: PIRAE 1 | R16: PIRAE 1 | S16: =AVERAGE(Précipitation!O5:O10) -> 0.43333333 | T16: =MAX(Précipitation!O5:O10) -> 2 | U16: =AVERAGE(Température!AB5:AB10) -> 23.95 | V16: =AVERAGE(Température!AC5:AC10) -> 32.1 | W16: 310.3 | X16: NO | Y16: Crête vallée | Z16: 5826 | AA16: 5615 | AB16: 1146 | AC16: =(AD16/31416) -> 0 | AD16: 0 | AE16: 20 | AF16: 40 | AG16: 70 | AH16: 0 | AI16: =Feuil2!J16/Feuil2!K16 -> 0.2 | AJ16: =Feuil2!J16+Feuil2!K16 -> 6 | AK16: =IF(COUNTIF(Feuil2!B86:B91,"Acridotheres tristis"),1,0) -> 0 | AL16: =IF(COUNTIF(Feuil2!C86:C91,"Natif"),1,0) -> 1 | AM16: =Feuil2!K16 -> 5 | AN16: 380 | AO16: 87
A17: OBelvedere_2 SMM09106 - 2703_31032024 - Gaia -17.57137, -149.52481 - Carte SD 128 Go EI extreme pro (humide) (PB lecture carte) | B17: OBelvedere_2 | C17: SMM9106 | D17: 45378 | E17: 45382 | F17: =AVERAGE(Soleil!$AR$5:$AR$10) -> 0.25305556 | G17: =AVERAGE(Soleil!$AS$5:$AS$10) -> 0.74972222 | H17: =AVERAGE(Soleil!$AT$5:$AT$10) -> 0.49652778 | I17: -17.57137 | J17: -149.52481 | K17: 720 | L17: Pirae | M17: Tahiti Nui | N17: Tahiti | O17: Société | P17: Forêt | Q17: PIRAE 1 | R17: PIRAE 1 | S17: =AVERAGE(Précipitation!P5:P9) -> 0.4 | T17: =MAX(Précipitation!P5:P9) -> 2 | U17: =AVERAGE(Température!AD5:AD9) -> 23.92 | V17: =AVERAGE(Température!AE5:AE9) -> 31.96 | W17: 311 | X17: NO | Y17: Crête vallée | Z17: 5433 | AA17: 5241 | AB17: 752 | AC17: =(AD17/31416) -> 0 | AD17: 0 | AE17: 90 | AF17: 30 | AG17: 40 | AH17: 0 | AI17: =Feuil2!J17/Feuil2!K17 -> 0.2 | AJ17: =Feuil2!J17+Feuil2!K17 -> 6 | AK17: =IF(COUNTIF(Feuil2!B92:B97,"Acridotheres tristis"),1,0) -> 0 | AL17: =IF(COUNTIF(Feuil2!C92:C97,"Natif"),1,0) -> 1 | AM17: =Feuil2!K17 -> 5 | AN17: 285 | AO17: 87
A18: OBelvedere_3 SMM09228 - 2703_02042024 - Gaia -17.56843, -149.52697 - Carte SD 128 Go 44 extreme pro | B18: OBelvedere_3 | C18: SMM09228 | D18: 45378 | E18: 45384 | F18: =AVERAGE(Soleil!$AU$5:$AU$10) -> 0.253125 | G18: =AVERAGE(Soleil!$AV$5:$AV$10) -> 0.7494213 | H18: =AVERAGE(Soleil!$AW$5:$AW$10) -> 0.49618056 | I18: -17.56843 | J18: -149.52697 | K18: 633 | L18: Pirae | M18: Tahiti Nui | N18: Tahiti | O18: Société | P18: Forêt | Q18: PIRAE 1 | R18: PIRAE 1 | S18: =AVERAGE(Précipitation!Q5:Q11) -> 0.37142857 | T18: =MAX(Précipitation!Q5:Q11) -> 2 | U18: =AVERAGE(Température!AF5:AF11) -> 23.942857 | V18: =AVERAGE(Température!AG5:AG11) -> 32.228571 | W18: 311.5 | X18: NO | Y18: Crête vallée | Z18: 5027 | AA18: 4868 | AB18: 341 | AC18: =(AD18/31416) -> 0 | AD18: 0 | AE18: 90 | AF18: 50 | AG18: 40 | AH18: 0 | AI18: =Feuil2!J18/Feuil2!K18 -> 0 | AJ18: =Feuil2!J18+Feuil2!K18 -> 5 | AK18: =IF(COUNTIF(Feuil2!B98:B102,"Acridotheres tristis"),1,0) -> 0 | AL18: =IF(COUNTIF(Feuil2!C98:C102,"Natif"),1,0) -> 0 | AM18: =Feuil2!K18 -> 5 | AN18: 315 | AO18: 87
A19: OBelvedere_4 SMM09234 - 2703_010424 - Gaia -17.56543, -149.52914 - Carte SD 128 Go 30 extreme pro (leger humide) (PB lecture carte) | B19: OBelvedere_4 | C19: SMM09234 | D19: 45378 | E19: 45383 | F19: =AVERAGE(Soleil!$AX$5:$AX$10) -> 0.253125 | G19: =AVERAGE(Soleil!$AY$5:$AY$10) -> 0.7494213 | H19: =AVERAGE(Soleil!$AZ$5:$AZ$10) -> 0.49618056 | I19: -17.56543 | J19: -149.52914 | K19: 592 | L19: Pirae | M19: Tahiti Nui | N19: Tahiti | O19: Société | P19: Forêt | Q19: PIRAE 1 | R19: PIRAE 1 | S19: =AVERAGE(Précipitation!R5:R10) -> 0.43333333 | T19: =MAX(Précipitation!R5:R10) -> 2 | U19: =AVERAGE(Température!AH5:AH10) -> 23.95 | V19: =AVERAGE(Température!AI5:AI10) -> 32.1 | W19: 312 | X19: NO | Y19: Crête vallée | Z19: 4625 | AA19: 4501 | AB19: 40.3 | AC19: =(AD19/31416) -> 0.036304113 | AD19: =711+47.8+182+40+47.1+11.9+8.43+36.3+56 -> 1140.53 | AE19: 80 | AF19: 40 | AG19: 40 | AH19: 10 | AI19: =Feuil2!J19/Feuil2!K19 -> 0.16666667 | AJ19: =Feuil2!J19+Feuil2!K19 -> 7 | AK19: =IF(COUNTIF(Feuil2!B103:B109,"Acridotheres tristis"),1,0) -> 0 | AL19: =IF(COUNTIF(Feuil2!C103:C109,"Natif"),1,0) -> 1 | AM19: =Feuil2!K19 -> 6 | AN19: 365 | AO19: 87
A20: OBelvedere_5 SMM09021 - 2703_01042024 - Gaia -17.56375, -149.53238 - Carte SD 128 Go T5 extreme | B20: OBelvedere_5 | C20: SMM09021 | D20: 45378 | E20: 45383 | F20: =AVERAGE(Soleil!$BA$5:$BA$10) -> 0.253125 | G20: =AVERAGE(Soleil!$BB$5:$BB$10) -> 0.7494213 | H20: =AVERAGE(Soleil!$BC$5:$BC$10) -> 0.49618056 | I20: -17.56375 | J20: -149.53238 | K20: 428 | L20: Pirae | M20: Tahiti Nui | N20: Tahiti | O20: Société | P20: Forêt | Q20: PIRAE 1 | R20: PIRAE 1 | S20: =AVERAGE(Précipitation!S5:S9) -> 0.4 | T20: =MAX(Précipitation!S5:S9) -> 2 | U20: =AVERAGE(Température!AJ5:AJ10) -> 23.95 | V20: =AVERAGE(Température!AK5:AK10) -> 32.1 | W20: 311.5 | X20: NO | Y20: Crête vallée | Z20: 4267 | AA20: 4258 | AB20: 217 | AC20: =(AD20/31416) -> 0 | AD20: 0 | AE20: 80 | AF20: 60 | AG20: 50 | AH20: 5 | AI20: =Feuil2!J20/Feuil2!K20 -> 0.2 | AJ20: =Feuil2!J20+Feuil2!K20 -> 6 | AK20: =IF(COUNTIF(Feuil2!B110:B115,"Acridotheres tristis"),1,0) -> 1 | AL20: =IF(COUNTIF(Feuil2!C110:C115,"Natif"),1,0) -> 1 | AM20: =Feuil2!K20 -> 5 | AN20: 310 | AO20: 87
A21: OBelvedere_6 SMM09080 - 2703_300324 - Gaia -17.55964, -149.53662 - Carte SD 64 Go E4 extreme | B21: OBelvedere_6 | C21: SMM09080 | D21: 45378 | E21: 45381 | F21: =AVERAGE(Soleil!$BD$5:$BD$10) -> 0.25295139 | G21: =AVERAGE(Soleil!$BE$5:$BE$10) -> 0.75 | H21: =AVERAGE(Soleil!$BF$5:$BF$10) -> 0.496875 | I21: -17.55964 | J21: -149.53662 | K21: 294 | L21: Pirae | M21: Tahiti Nui | N21: Tahiti | O21: Société | P21: Forêt | Q21: PIRAE 1 | R21: PIRAE 1 | S21: =AVERAGE(Précipitation!T5:T8) -> 0 | T21: =MAX(Précipitation!T5:T8) -> 0 | U21: =AVERAGE(Température!AL5:AL8) -> 23.75 | V21: =AVERAGE(Température!AM5:AM8) -> 32.525 | W21: 311.7 | X21: NO | Y21: Crête vallée | Z21: 3644 | AA21: 3782 | AB21: 393 | AC21: =(AD21/31416) -> 0 | AD21: 0 | AE21: 90 | AF21: 30 | AG21: 40 | AH21: 5 | AI21: =Feuil2!J21/Feuil2!K21 -> 0.25 | AJ21: =Feuil2!J21+Feuil2!K21 -> 10 | AK21: =IF(COUNTIF(Feuil2!B116:B125,"Acridotheres tristis"),1,0) -> 1 | AL21: =IF(COUNTIF(Feuil2!C116:C125,"Natif"),1,0) -> 1 | AM21: =Feuil2!K21 -> 8 | AN21: 195 | AO21: 87
A22: OBelvedere_6.5 SMM09021 - 0205_060524 - Gaia -17.55615, -149.53839 | B22: OBelvedere_6.5 | C22: SMM09021 | D22: 45414 | E22: 45418 | F22: =AVERAGE(Soleil!$BG$5:$BG$10) -> 0.25875 | G22: =AVERAGE(Soleil!$BH$5:$BH$10) -> 0.73319444 | H22: =AVERAGE(Soleil!$BI$5:$BI$10) -> 0.47402778 | I22: -17.55615 | J22: -149.53839 | K22: 256 | L22: Pirae | M22: Tahiti Nui | N22: Tahiti | O22: Société | P22: Forêt | Q22: PIRAE 1 | R22: PIRAE 1 | S22: =AVERAGE(Précipitation!U5:U9) -> 0.08 | T22: =MAX(Précipitation!U5:U9) -> 0.2 | U22: =AVERAGE(Température!AN5:AN9) -> 22.96 | V22: =AVERAGE(Température!AO5:AO9) -> 32.24 | W22: 312.5 | X22: NO | Y22: Crête vallée | Z22: 3211 | AA22: 3404 | AB22: 210 | AC22: =(AD22/31416) -> 0 | AD22: 0 | AE22: 90 | AF22: 60 | AG22: 0 | AH22: 5 | AI22: =Feuil2!J22/Feuil2!K22 -> 0.5 | AJ22: =Feuil2!J22+Feuil2!K22 -> 6 | AK22: =IF(COUNTIF(Feuil2!B126:B131,"Acridotheres tristis"),1,0) -> 0 | AL22: =IF(COUNTIF(Feuil2!C126:C131,"Natif"),1,0) -> 1 | AM22: =Feuil2!K22 -> 4 | AN22: 275 | AO22: 123
A23: OBelvedere_7 SMM09337 - 2703_010424 - Gaia -17.55266, -149.53922 - Carte SD 64 Go A20 extreme | B23: OBelvedere_7 | C23: SMM09337 | D23: 45378 | E23: 45383 | F23: =AVERAGE(Soleil!$BJ$5:$BJ$10) -> 0.253125 | G23: =AVERAGE(Soleil!$BK$5:$BK$10) -> 0.7494213 | H23: =AVERAGE(Soleil!$BL$5:$BL$10) -> 0.49618056 | I23: -17.55266 | J23: -149.53822 | K23: 173 | L23: Pirae | M23: Tahiti Nui | N23: Tahiti | O23: Société | P23: Forêt | Q23: PIRAE 1 | R23: PIRAE 1 | S23: =AVERAGE(Précipitation!V5:V10) -> 0.43333333 | T23: =MAX(Précipitation!V5:V10) -> 2 | U23: =AVERAGE(Température!AP5:AP10) -> 23.95 | V23: =AVERAGE(Température!AQ5:AQ10) -> 32.1 | W23: 313.8 | X23: NO | Y23: Crête vallée | Z23: 2882 | AA23: 3017 | AB23: 226 | AC23: =(AD23/31416) -> 0 | AD23: 0 | AE23: 90 | AF23: 30 | AG23: 30 | AH23: 5 | AI23: =Feuil2!J23/Feuil2!K23 -> 0 | AJ23: =Feuil2!J23+Feuil2!K23 -> 5 | AK23: =IF(COUNTIF(Feuil2!B132:B136,"Acridotheres tristis"),1,0) -> 0 | AL23: =IF(COUNTIF(Feuil2!C132:C136,"Natif"),1,0) -> 0 | AM23: =Feuil2!K23 -> 5 | AN23: 340 | AO23: 87
A24: OBelvedere_7.5 SMM02553 - 0205_080524 - Gaia -17.54944, -149.54273  | B24: OBelvedere_7.5 | C24: SMM02553 | D24: 45414 | E24: 45420 | F24: =AVERAGE(Soleil!$BM$5:$BM$11) -> 0.25902778 | G24: =AVERAGE(Soleil!$BN$5:$BN$11) -> 0.7328373 | H24: =AVERAGE(Soleil!$BO$5:$BO$11) -> 0.4735119 | I24: -17.54944 | J24: -149.54273 | K24: 177 | L24: Pirae | M24: Tahiti Nui | N24: Tahiti | O24: Société | P24: Forêt | Q24: PIRAE 1 | R24: PIRAE 1 | S24: =AVERAGE(Précipitation!W5:W11) -> 0.057142857 | T24: =MAX(Précipitation!W5:W11) -> 0.2 | U24: =AVERAGE(Température!AR5:AR11) -> 23.028571 | V24: =AVERAGE(Température!AS5:AS11) -> 32.142857 | W24: 313.5 | X24: NO | Y24: Hors vallée | Z24: 2339 | AA24: 2679 | AB24: 116 | AC24: =(AD24/31416) -> 0 | AD24: 0 | AE24: 90 | AF24: 60 | AG24: 0 | AH24: 5 | AI24: =Feuil2!J24/Feuil2!K24 -> 0 | AJ24: =Feuil2!J24+Feuil2!K24 -> 6 | AK24: =IF(COUNTIF(Feuil2!B137:B142,"Acridotheres tristis"),1,0) -> 0 | AL24: =IF(COUNTIF(Feuil2!C137:C142,"Natif"),1,0) -> 0 | AM24: =Feuil2!K24 -> 6 | AN24: 370 | AO24: 123
A25: OBelvedere_8 SMM02752 - 2703_02042024 - Gaia -17.54568, -149.54451 - Carte SD 32 Go 40 extreme | B25: OBelvedere_8 | C25: SMM02752 | D25: 45378 | E25: 45384 | F25: =AVERAGE(Soleil!$BP$5:$BP$11) -> 0.2531746 | G25: =AVERAGE(Soleil!$BQ$5:$BQ$11) -> 0.74910714 | H25: =AVERAGE(Soleil!$BR$5:$BR$11) -> 0.49583333 | I25: -17.54568 | J25: -149.54451 | K25: 163 | L25: Pirae | M25: Tahiti Nui | N25: Tahiti | O25: Société | P25: Suburbain | Q25: PIRAE 1 | R25: PIRAE 1 | S25: =AVERAGE(Précipitation!X5:X11) -> 0.37142857 | T25: =MAX(Précipitation!X5:X11) -> 2 | U25: =AVERAGE(Température!AT5:AT11) -> 23.942857 | V25: =AVERAGE(Température!AU5:AU11) -> 32.228571 | W25: 314.2 | X25: NO | Y25: Hors vallée | Z25: 1883 | AA25: 2228 | AB25: 22.3 | AC25: =(AD25/31416) -> 0.33894194 | AD25: =1094+41.6+4113+1335+709+3130+95.8+62+11.5+23.9+20.6+11.8 -> 10648.2 | AE25: 40 | AF25: 20 | AG25: 0 | AH25: 50 | AI25: =Feuil2!J25/Feuil2!K25 -> 0 | AJ25: =Feuil2!J25+Feuil2!K25 -> 7 | AK25: =IF(COUNTIF(Feuil2!B143:B149,"Acridotheres tristis"),1,0) -> 1 | AL25: =IF(COUNTIF(Feuil2!C143:C149,"Natif"),1,0) -> 0 | AM25: =Feuil2!K25 -> 7 | AN25: 390 | AO25: 87
A26: OBelvedere_9 SMM02553 - 2703_01042024 - Gaia -17.53843, -149.54800 - Carte SD 64 Go extreme pro | B26: OBelvedere_9 | C26: SMM02553 | D26: 45378 | E26: 45383 | F26: =AVERAGE(Soleil!$BS$5:$BS$10) -> 0.253125 | G26: =AVERAGE(Soleil!$BT$5:$BT$10) -> 0.7494213 | H26: =AVERAGE(Soleil!$BU$5:$BU$10) -> 0.49618056 | I26: -17.53843 | J26: -149.54800 | K26: 58 | L26: Pirae | M26: Tahiti Nui | N26: Tahiti | O26: Société | P26: Suburbain | Q26: PIRAE 1 | R26: PIRAE 1 | S26: =AVERAGE(Précipitation!Y5:Y10) -> 0.43333333 | T26: =MAX(Précipitation!Y5:Y10) -> 2 | U26: =AVERAGE(Température!AV5:AV10) -> 23.95 | V26: =AVERAGE(Température!AW5:AW10) -> 32.1 | W26: 315.4 | X26: NO | Y26: Hors vallée | Z26: 992 | AA26: 1373 | AB26: 22.4 | AC26: =(AD26/31416) -> 0.35670996 | AD26: =226+94.4+282+1892+398+2823+2304+1244+143+185+1615 -> 11206.4 | AE26: 50 | AF26: 10 | AG26: 0 | AH26: 50 | AI26: =Feuil2!J26/Feuil2!K26 -> 0 | AJ26: =Feuil2!J26+Feuil2!K26 -> 7 | AK26: =IF(COUNTIF(Feuil2!B150:B156,"Acridotheres tristis"),1,0) -> 1 | AL26: =IF(COUNTIF(Feuil2!C150:C156,"Natif"),1,0) -> 0 | AM26: =Feuil2!K26 -> 7 | AN26: 360 | AO26: 87
A27: Papeete_2 SMM09228 - 0205_070524 - Gaia -17.53502, -149.55922 | B27: Papeete_2 | C27: SMM09228 | D27: 45414 | E27: 45419 | F27: =AVERAGE(Soleil!$BV$5:$BV$10) -> 0.25914352 | G27: =AVERAGE(Soleil!$BW$5:$BW$10) -> 0.73310185 | H27: =AVERAGE(Soleil!$BX$5:$BX$10) -> 0.47361111 | I27: -17.53502 | J27: -149.55922 | K27: 14 | L27: Papeete | M27: Tahiti Nui | N27: Tahiti | O27: Société | P27: Urbain | Q27: PAPEETE 2, PAPEETE3 | R27: PIRAE 1 | S27: =AVERAGE(Précipitation!Z5:Z10,Précipitation!Z12:Z17) -> 0 | T27: =MAX(Précipitation!Z5:Z10,Précipitation!Z12:Z17) -> 0 | U27: =AVERAGE(Température!AX5:AX10) -> 23.016667 | V27: =AVERAGE(Température!AY5:AY10) -> 32.35 | W27: 313.3 | X27: NO | Y27: Hors vallée | Z27: 180 | AA27: 873 | AB27: 7.27 | AC27: =(AD27/31416) -> 0.8724217 | AD27: 27408 | AE27: 30 | AF27: 0 | AG27: 20 | AH27: 70 | AI27: =Feuil2!J27/Feuil2!K27 -> 0 | AJ27: =Feuil2!J27+Feuil2!K27 -> 6 | AK27: =IF(COUNTIF(Feuil2!B157:B162,"Acridotheres tristis"),1,0) -> 1 | AL27: =IF(COUNTIF(Feuil2!C157:C162,"Natif"),1,0) -> 0 | AM27: =Feuil2!K27 -> 6 | AN27: 345 | AO27: 123
A28: Papeete_3 SMM09233 - 0205_070524 - Gaia -17.53199, -149.56194 | B28: Papeete_3 | C28: SMM09233 | D28: 45414 | E28: 45419 | F28: =AVERAGE(Soleil!$BY$5:$BY$10) -> 0.25914352 | G28: =AVERAGE(Soleil!$BZ$5:$BZ$10) -> 0.73310185 | H28: =AVERAGE(Soleil!$CA$5:$CA$10) -> 0.47361111 | I28: -17.53199 | J28: -149.56194 | K28: 10 | L28: Papeete | M28: Tahiti Nui | N28: Tahiti | O28: Société | P28: Urbain | Q28: PAPEETE 2, PAPEETE3 | R28: PIRAE 1 | S28: =AVERAGE(Précipitation!AA5:AA10,Précipitation!AA12:AA17) -> 0 | T28: =MAX(Précipitation!AA5:AA10,Précipitation!AA12:AA17) -> 0 | U28: =AVERAGE(Température!AZ5:AZ10) -> 23.016667 | V28: =AVERAGE(Température!BA5:BA10) -> 32.35 | W28: 313.5 | X28: NO | Y28: Hors vallée | Z28: 237 | AA28: 476 | AB28: 2.75 | AC28: =(AD28/31416) -> 0.70643621 | AD28: =5392+323+58.7+145+87.7+1715+2957+187+2352+638+173+221+4780+2614+191+359 -> 22193.4 | AE28: 10 | AF28: 10 | AG28: 20 | AH28: 70 | AI28: =Feuil2!J28/Feuil2!K28 -> 0 | AJ28: =Feuil2!J28+Feuil2!K28 -> 7 | AK28: =IF(COUNTIF(Feuil2!B163:B169,"Acridotheres tristis"),1,0) -> 1 | AL28: =IF(COUNTIF(Feuil2!C163:C169,"Natif"),1,0) -> 0 | AM28: =Feuil2!K28 -> 7 | AN28: 345 | AO28: 123
A29: Papeete_4 SMM09037 - 0205_070524 - Gaia -17.53325, -149.56791 | B29: Papeete_4 | C29: SMM09037 | D29: 45414 | E29: 45419 | F29: =AVERAGE(Soleil!$CB$5:$CB$10) -> 0.25914352 | G29: =AVERAGE(Soleil!$CC$5:$CC$10) -> 0.73310185 | H29: =AVERAGE(Soleil!$CD$5:$CD$10) -> 0.47361111 | I29: -17.53325 | J29: -149.56791 | K29: 8 | L29: Papeete | M29: Tahiti Nui | N29: Tahiti | O29: Société | P29: Urbain | Q29: PAPEETE 2, PAPEETE3 | R29: PIRAE 1 | S29: =AVERAGE(Précipitation!AB5:AB10,Précipitation!AB12:AB17) -> 0 | T29: =MAX(Précipitation!AB5:AB10,Précipitation!AB12:AB17) -> 0 | U29: =AVERAGE(Température!BB5:BB10) -> 23.016667 | V29: =AVERAGE(Température!BC5:BC10) -> 32.35 | W29: 311.7 | X29: NO | Y29: Hors vallée | Z29: 336 | AA29: 202 | AB29: 7.87 | AC29: =(AD29/31416) -> 0.87764197 | AD29: 27572 | AE29: 0 | AF29: 30 | AG29: 10 | AH29: 70 | AI29: =Feuil2!J29/Feuil2!K29 -> 0 | AJ29: =Feuil2!J29+Feuil2!K29 -> 5 | AK29: =IF(COUNTIF(Feuil2!B170:B174,"Acridotheres tristis"),1,0) -> 1 | AL29: =IF(COUNTIF(Feuil2!C170:C174,"Natif"),1,0) -> 0 | AM29: =Feuil2!K29 -> 5 | AN29: 345 | AO29: 123 | AP29: 1/3 du cercle Flouté par la base navale
A30: Papeete_5 SMM09009 - 0205_050524 - Gaia -17.52491, -149.55676 | B30: Papeete_5 | C30: SMM09009 | D30: 45414 | E30: 45417 | F30: =AVERAGE(Soleil!$CE$5:$CE$10) -> 0.25885417 | G30: =AVERAGE(Soleil!$CF$5:$CF$10) -> 0.73333333 | H30: =AVERAGE(Soleil!$CG$5:$CG$10) -> 0.47413194 | I30: -17.52491 | J30: -149.55676 | K30: 6 | L30: Papeete | M30: Tahiti Nui | N30: Tahiti | O30: Société | P30: Urbain | Q30: PAPEETE 2, PAPEETE3 | R30: PIRAE 1 | S30: =AVERAGE(Précipitation!AC5:AC8,Précipitation!AC12:AC15) -> 0 | T30: =MAX(Précipitation!AC5:AC8,Précipitation!AC12:AC15) -> 0 | U30: =AVERAGE(Température!BD5:BD8) -> 22.75 | V30: =AVERAGE(Température!BE5:BE8) -> 32.05 | W30: 316.8 | X30: NO | Y30: Hors vallée | Z30: 765 | AA30: 60.2 | AB30: 5 | AC30: =(AD30/31416) -> 0.43166858 | AD30: =174+392+380+1185+20.7+4115+17.7+12.3+13.6+53.6+3438+896+46.4+44+1891+307+575 -> 13561.3 | AE30: 10 | AF30: 40 | AG30: 30 | AH30: 40 | AI30: =Feuil2!J30/Feuil2!K30 -> 0 | AJ30: =Feuil2!J30+Feuil2!K30 -> 5 | AK30: =IF(COUNTIF(Feuil2!B175:B179,"Acridotheres tristis"),1,0) -> 1 | AL30: =IF(COUNTIF(Feuil2!C175:C179,"Natif"),1,0) -> 0 | AM30: =Feuil2!K30 -> 5 | AN30: 225 | AO30: 123
A31: PI_Belvedere_1 SMM02752 - 1902_24022024 - B0369 - Gaia -17.78532, -149.24700 - Carte SD 64 Go disk3s1 A6 extreme pro | B31: PI_Belvedere_1 | C31: SMM02752 | D31: 45341 | E31: 45346 | F31: =AVERAGE(Soleil!$CH$5:$CH$10) -> 0.24571759 | G31: =AVERAGE(Soleil!$CI$5:$CI$10) -> 0.76782407 | H31: =AVERAGE(Soleil!$CJ$5:$CJ$10) -> 0.521875 | I31: -17.78532 | J31: -149.24700 | K31: 749 | L31: Pueu | M31: Tahiti Iti | N31: Tahiti | O31: Société | P31: Forêt | Q31: AFAAHITI 2, AFAAHITI 4 | R31: AFAAHITI 2 | S31: =AVERAGE(Précipitation!AD5:AD10,Précipitation!AD12:AD17) -> 2.35 | T31: =MAX(Précipitation!AD5:AD10,Précipitation!AD12:AD17) -> 10.2 | U31: =AVERAGE(Température!BF5:BF10) -> 20.46 | V31: =AVERAGE(Température!BG5:BG10) -> 25.26 | W31: 302.4 | X31: NO | Y31: Plateau vallée | Z31: 5244 | AA31: 5297 | AB31: 745 | AC31: =(AD31/31416) -> 0 | AD31: 0 | AE31: 20 | AF31: 40 | AG31: 60 | AH31: 0 | AI31: =Feuil2!J31/Feuil2!K31 -> 0 | AJ31: =Feuil2!J31+Feuil2!K31 -> 4 | AK31: =IF(COUNTIF(Feuil2!B180:B183,"Acridotheres tristis"),1,0) -> 1 | AL31: =IF(COUNTIF(Feuil2!C180:C183,"Natif"),1,0) -> 0 | AM31: =Feuil2!K31 -> 4 | AN31: 350 | AO31: 50
A32: PI_Belvedere_2 SMM02553 - 1902_24022024 - B0368 - Gaia -17.78252, -149.24942 - Carte SD 32 Go 40 extreme | B32: PI_Belvedere_2 | C32: SMM02553 | D32: 45341 | E32: 45346 | F32: =AVERAGE(Soleil!$CK$5:$CK$10) -> 0.24571759 | G32: =AVERAGE(Soleil!$CL$5:$CL$10) -> 0.76782407 | H32: =AVERAGE(Soleil!$CM$5:$CM$10) -> 0.521875 | I32: -17.78252 | J32: -149.24942 | K32: 714 | L32: Pueu | M32: Tahiti Iti | N32: Tahiti | O32: Société | P32: Forêt | Q32: AFAAHITI 2, AFAAHITI 4 | R32: AFAAHITI 2 | S32: =AVERAGE(Précipitation!AE5:AE10,Précipitation!AE12:AE17) -> 2.35 | T32: =MAX(Précipitation!AE5:AE10,Précipitation!AE12:AE17) -> 10.2 | U32: =AVERAGE(Température!BH5:BH10) -> 20.46 | V32: =AVERAGE(Température!BI5:BI10) -> 25.26 | W32: 303.8 | X32: NO | Y32: Plateau vallée | Z32: 4900 | AA32: 4953 | AB32: 455 | AC32: =(AD32/31416) -> 0 | AD32: 0 | AE32: 40 | AF32: 60 | AG32: 50 | AH32: 0 | AI32: =Feuil2!J32/Feuil2!K32 -> 0.2 | AJ32: =Feuil2!J32+Feuil2!K32 -> 6 | AK32: =IF(COUNTIF(Feuil2!B184:B189,"Acridotheres tristis"),1,0) -> 0 | AL32: =IF(COUNTIF(Feuil2!C184:C189,"Natif"),1,0) -> 1 | AM32: =Feuil2!K32 -> 5 | AN32: 390 | AO32: 50
A33: PI_Belvedere_3 SMM02755 - 1902_24022024 - B0371 - Gaia -17.78001, -149.25222 - Carte SD 64 Go A20 extreme (un peu eau) | B33: PI_Belvedere_3 | C33: SMM02755 | D33: 45341 | E33: 45346 | F33: =AVERAGE(Soleil!$CN$5:$CN$10) -> 0.24571759 | G33: =AVERAGE(Soleil!$CO$5:$CO$10) -> 0.76782407 | H33: =AVERAGE(Soleil!$CP$5:$CP$10) -> 0.521875 | I33: -17.78001 | J33: -149.25222 | K33: 670 | L33: Pueu | M33: Tahiti Iti | N33: Tahiti | O33: Société | P33: Forêt | Q33: AFAAHITI 2, AFAAHITI 4 | R33: AFAAHITI 2 | S33: =AVERAGE(Précipitation!AF5:AF10,Précipitation!AF12:AF17) -> 2.35 | T33: =MAX(Précipitation!AF5:AF10,Précipitation!AF12:AF17) -> 10.2 | U33: =AVERAGE(Température!BJ4:BJ10) -> 20.46 | V33: =AVERAGE(Température!BK4:BK10) -> 25.26 | W33: 304.5 | X33: NO | Y33: Plateau vallée | Z33: 4589 | AA33: 4643 | AB33: 221 | AC33: =(AD33/31416) -> 0 | AD33: 0 | AE33: 60 | AF33: 60 | AG33: 60 | AH33: 0 | AI33: =Feuil2!J33/Feuil2!K33 -> 0.25 | AJ33: =Feuil2!J33+Feuil2!K33 -> 5 | AK33: =IF(COUNTIF(Feuil2!B190:B194,"Acridotheres tristis"),1,0) -> 1 | AL33: =IF(COUNTIF(Feuil2!C190:C194,"Natif"),1,0) -> 1 | AM33: =Feuil2!K33 -> 4 | AN33: 365 | AO33: 50
A34: PI_Belvedere_4 SMM09080 - 1902_24022024 - B0372 - GAIA -17.77712, -149.25440 - Carte SD 128 Go T5 extreme (mouillé) | B34: PI_Belvedere_4 | C34: SMM09080 | D34: 45341 | E34: 45346 | F34: =AVERAGE(Soleil!$CQ$5:$CQ$10) -> 0.24571759 | G34: =AVERAGE(Soleil!$CR$5:$CR$10) -> 0.76782407 | H34: =AVERAGE(Soleil!$CS$5:$CS$10) -> 0.521875 | I34: -17.77712 | J34: -149.25440 | K34: 637 | L34: Pueu | M34: Tahiti Iti | N34: Tahiti | O34: Société | P34: Forêt | Q34: AFAAHITI 2, AFAAHITI 4 | R34: AFAAHITI 2 | S34: =AVERAGE(Précipitation!AG5:AG10,Précipitation!AG12:AG17) -> 2.35 | T34: =MAX(Précipitation!AG5:AG10,Précipitation!AG12:AG17) -> 10.2 | U34: =AVERAGE(Température!BL5:BL10) -> 20.46 | V34: =AVERAGE(Température!BM5:BM10) -> 25.26 | W34: 305.8 | X34: NO | Y34: Plateau vallée | Z34: 4251 | AA34: 4313 | AB34: 348 | AC34: =(AD34/31416) -> 0.051056786 | AD34: 1604 | AE34: 15 | AF34: 40 | AG34: 70 | AH34: 0 | AI34: =Feuil2!J34/Feuil2!K34 -> 0.28571429 | AJ34: =Feuil2!J34+Feuil2!K34 -> 9 | AK34: =IF(COUNTIF(Feuil2!B195:B203,"Acridotheres tristis"),1,0) -> 1 | AL34: =IF(COUNTIF(Feuil2!C195:C203,"Natif"),1,0) -> 1 | AM34: =Feuil2!K34 -> 7 | AN34: 295 | AO34: 50
A35: PI_Belvedere_5 SMM09233 - 1902_24022024 - B0373 - Gaia -17.77749, -149.25852 - Carte SD 64 Go E4 extreme | B35: PI_Belvedere_5 | C35: SMM09233 | D35: 45341 | E35: 45346 | F35: =AVERAGE(Soleil!$CT$5:$CT$10) -> 0.24571759 | G35: =AVERAGE(Soleil!$CU$5:$CU$10) -> 0.76782407 | H35: =AVERAGE(Soleil!$CV$5:$CV$10) -> 0.521875 | I35: -17.77749 | J35: -149.25852 | K35: 567 | L35: Pueu | M35: Tahiti Iti | N35: Tahiti | O35: Société | P35: Prairie | Q35: AFAAHITI 2, AFAAHITI 4 | R35: AFAAHITI 2 | S35: =AVERAGE(Précipitation!AH5:AH10,Précipitation!AH12:AH17) -> 2.35 | T35: =MAX(Précipitation!AH5:AH10,Précipitation!AH12:AH17) -> 10.2 | U35: =AVERAGE(Température!BN5:BN10) -> 20.46 | V35: =AVERAGE(Température!BO5:BO10) -> 25.26 | W35: 303.1 | X35: NO | Y35: Plateau vallée | Z35: 4257 | AA35: 4288 | AB35: 92.8 | AC35: =(AD35/31416) -> 0.02535014 | AD35: =354+41.9+13.8+322+64.7 -> 796.4 | AE35: 10 | AF35: 0 | AG35: 90 | AH35: 5 | AI35: =Feuil2!J35/Feuil2!K35 -> 0.28571429 | AJ35: =Feuil2!J35+Feuil2!K35 -> 9 | AK35: =IF(COUNTIF(Feuil2!B204:B212,"Acridotheres tristis"),1,0) -> 1 | AL35: =IF(COUNTIF(Feuil2!C204:C212,"Natif"),1,0) -> 1 | AM35: =Feuil2!K35 -> 7 | AN35: 360 | AO35: 50
A36: PI_Belvedere_6 SMM09337 - 1902_24022024 - B0374 - Gaia -17.77471, -149.26167 - Carte SD 64 Go E27 extreme | B36: PI_Belvedere_6 | C36: SMM09337 | D36: 45341 | E36: 45346 | F36: =AVERAGE(Soleil!$CW$5:$CW$10) -> 0.24571759 | G36: =AVERAGE(Soleil!$CX$5:$CX$10) -> 0.76782407 | H36: =AVERAGE(Soleil!$CY$5:$CY$10) -> 0.521875 | I36: -17.77471 | J36: -149.26167 | K36: 515 | L36: Pueu | M36: Tahiti Iti | N36: Tahiti | O36: Société | P36: Prairie | Q36: AFAAHITI 2, AFAAHITI 4 | R36: AFAAHITI 2 | S36: =AVERAGE(Précipitation!AI5:AI10,Précipitation!AI12:AI17) -> 2.35 | T36: =MAX(Précipitation!AI4:AI10,Précipitation!AI12:AI17) -> 10.2 | U36: =AVERAGE(Température!BP5:BP10) -> 20.46 | V36: =AVERAGE(Température!BQ5:BQ10) -> 25.26 | W36: 303.8 | X36: NO | Y36: Plateau vallée | Z36: 3961 | AA36: 3991 | AB36: 220 | AC36: =(AD36/31416) -> 0.013174815 | AD36: =51.3+58.9+89+24.8+35.2+10+31.7+113 -> 413.9 | AE36: 10 | AF36: 0 | AG36: 90 | AH36: 5 | AI36: =Feuil2!J36/Feuil2!K36 -> 0.33333333 | AJ36: =Feuil2!J36+Feuil2!K36 -> 8 | AK36: =IF(COUNTIF(Feuil2!B213:B220,"Acridotheres tristis"),1,0) -> 1 | AL36: =IF(COUNTIF(Feuil2!C213:C220,"Natif"),1,0) -> 1 | AM36: =Feuil2!K36 -> 6 | AN36: 360 | AO36: 50
A37: PI_Belvedere_7 SMM09009 - 1902_24022024 - B0375 - Gaia -17.77101, -149.26569 - Carte SD 32 Go 38 extreme | B37: PI_Belvedere_7 | C37: SMM09009 | D37: 45341 | E37: 45346 | F37: =AVERAGE(Soleil!$CZ$5:$CZ$10) -> 0.24571759 | G37: =AVERAGE(Soleil!$DA$5:$DA$10) -> 0.76782407 | H37: =AVERAGE(Soleil!$DB$5:$DB$10) -> 0.521875 | I37: -17.77101 | J37: -149.26569 | K37: 451 | L37: Pueu | M37: Tahiti Iti | N37: Tahiti | O37: Société | P37: Prairie | Q37: AFAAHITI 2, AFAAHITI 4 | R37: AFAAHITI 2 | S37: =AVERAGE(Précipitation!AJ5:AJ10,Précipitation!AJ12:AJ17) -> 2.35 | T37: =MAX(Précipitation!AJ5:AJ10,Précipitation!AJ12:AJ17) -> 10.2 | U37: =AVERAGE(Température!BR5:BR10) -> 20.46 | V37: =AVERAGE(Température!BS5:BS10) -> 25.26 | W37: 304.6 | X37: NO | Y37: Plateau vallée | Z37: 3617 | AA37: 3648 | AB37: 204 | AC37: =(AD37/31416) -> 0.013585434 | AD37: =119+17.2+155+29.8+19.7+46.6+39.5 -> 426.8 | AE37: 15 | AF37: 0 | AG37: 90 | AH37: 5 | AI37: =Feuil2!J37/Feuil2!K37 -> 0.11111111 | AJ37: =Feuil2!J37+Feuil2!K37 -> 10 | AK37: =IF(COUNTIF(Feuil2!B221:B230,"Acridotheres tristis"),1,0) -> 1 | AL37: =IF(COUNTIF(Feuil2!C221:C230,"Natif"),1,0) -> 1 | AM37: =Feuil2!K37 -> 9 | AN37: 390 | AO37: 50
A38: PI_Belvedere_8 SMM09021 - 1902_25022024 - B0376 - Gaia -17.76659, -149.26981 - Carte SD 32 Go 42 extreme | B38: PI_Belvedere_8 | C38: SMM09021 | D38: 45341 | E38: 45347 | F38: =AVERAGE(Soleil!$DC$5:$DC$10) -> 0.24571759 | G38: =AVERAGE(Soleil!$DD$5:$DD$10) -> 0.76782407 | H38: =AVERAGE(Soleil!$DE$5:$DE$10) -> 0.521875 | I38: -17.76659 | J38: -149.26981 | K38: 408 | L38: Pueu | M38: Tahiti Iti | N38: Tahiti | O38: Société | P38: Prairie | Q38: AFAAHITI 2, AFAAHITI 4 | R38: AFAAHITI 2 | S38: =AVERAGE(Précipitation!AK5:AK10,Précipitation!AK12:AK17) -> 2.35 | T38: =MAX(Précipitation!AK5:AK10,Précipitation!AK12:AK17) -> 10.2 | U38: =AVERAGE(Température!BT5:BT11) -> 20.6 | V38: =AVERAGE(Température!BU5:BU11) -> 25.316667 | W38: 305.8 | X38: NO | Y38: Plateau vallée | Z38: 3139 | AA38: 3196 | AB38: 257 | AC38: =(AD38/31416) -> 0.0031066972 | AD38: =34.7+46.8+16.1 -> 97.6 | AE38: 30 | AF38: 0 | AG38: 80 | AH38: 5 | AI38: =Feuil2!J38/Feuil2!K38 -> 0.28571429 | AJ38: =Feuil2!J38+Feuil2!K38 -> 9 | AK38: =IF(COUNTIF(Feuil2!B231:B239,"Acridotheres tristis"),1,0) -> 1 | AL38: =IF(COUNTIF(Feuil2!C231:C239,"Natif"),1,0) -> 1 | AM38: =Feuil2!K38 -> 7 | AN38: 390 | AO38: 50
A39: PI_Belvedere_9 SMM09307 - 1902_25022024 - B0377 - Gaia -17.76375, -149.27422 - Carte SD 32 Go J noire | B39: PI_Belvedere_9 | C39: SMM09307 | D39: 45341 | E39: 45347 | F39: =AVERAGE(Soleil!$DF$5:$DF$10) -> 0.24571759 | G39: =AVERAGE(Soleil!$DG$5:$DG$10) -> 0.76782407 | H39: =AVERAGE(Soleil!$DH$5:$DH$10) -> 0.521875 | I39: -17.76375 | J39: -149.27422 | K39: 329 | L39: Pueu | M39: Tahiti Iti | N39: Tahiti | O39: Société | P39: Forêt | Q39: AFAAHITI 2, AFAAHITI 4 | R39: AFAAHITI 2 | S39: =AVERAGE(Précipitation!AL5:AL10,Précipitation!AL12:AL17) -> 2.35 | T39: =MAX(Précipitation!AL5:AL10,Précipitation!AL12:AL17) -> 10.2 | U39: =AVERAGE(Température!BV5:BV11) -> 20.6 | V39: =AVERAGE(Température!BW5:BW11) -> 25.316667 | W39: 305.6 | X39: NO | Y39: Plateau vallée | Z39: 2851 | AA39: 2968 | AB39: 127 | AC39: =(AD39/31416) -> 0.010450089 | AD39: =98.6+128+90.7+11 -> 328.3 | AE39: 60 | AF39: 10 | AG39: 40 | AH39: 0 | AI39: =Feuil2!J39/Feuil2!K39 -> 0.14285714 | AJ39: =Feuil2!J39+Feuil2!K39 -> 8 | AK39: =IF(COUNTIF(Feuil2!B240:B247,"Acridotheres tristis"),1,0) -> 1 | AL39: =IF(COUNTIF(Feuil2!C240:C247,"Natif"),1,0) -> 1 | AM39: =Feuil2!K39 -> 7 | AN39: 370 | AO39: 50
A40: PI_Embouchure_1 SMM09228 - 1502_20022024 - A0469 - Gaia -17.87781, -149.18525 - Carte SD 128 Go 30 extreme pro (mouille) | B40: PI_Embouchure_1 | C40: SMM09228 | D40: 45337 | E40: 45342 | F40: =AVERAGE(Soleil!$DI$5:$DI$10) -> 0.24467593 | G40: =AVERAGE(Soleil!$DJ$5:$DJ$10) -> 0.76967593 | H40: =AVERAGE(Soleil!$DK$5:$DK$10) -> 0.52465278 | I40: -17.87781 | J40: -149.18525 | K40: 12 | L40: Teahupoo | M40: Tahiti Iti | N40: Tahiti | O40: Société | P40: Forêt | Q40: TEAHUPOO, TEAHUPOO 1, TEAHUPOO 2 | R40: TEAHUPOO | S40: =AVERAGE(Précipitation!AM5:AM10,Précipitation!AM12:AM17,Précipitation!AM19:AM24) -> 0.88888889 | T40: =MAX(Précipitation!AM5:AM10,Précipitation!AM12:AM17,Précipitation!AM19:AM24) -> 6.4 | U40: =AVERAGE(Température!BX5:BX10) -> 23.883333 | V40: =AVERAGE(Température!BY5:BY10) -> 32.633333 | W40: 161.8 | X40: SSE | Y40: Hors vallée | Z40: 7307 | AA40: 66.4 | AB40: 16.1 | AC40: =(AD40/31416) -> 0.010035969 | AD40: =28+82.5+8.69+82.6+73.2+11.4+28.9 -> 315.29 | AE40: 50 | AF40: 40 | AG40: 10 | AH40: 5 | AI40: =Feuil2!J40/Feuil2!K40 -> 0 | AJ40: =Feuil2!J40+Feuil2!K40 -> 6 | AK40: =IF(COUNTIF(Feuil2!B248:B253,"Acridotheres tristis"),1,0) -> 1 | AL40: =IF(COUNTIF(Feuil2!C248:C253,"Natif"),1,0) -> 0 | AM40: =Feuil2!K40 -> 6 | AN40: 345 | AO40: 46
...

Sheet Description_Champ_Feuil1
A1: Nom_Tab | B1: Nom_Complet | C1: Description | K1: Variables
A2: Fichier | B2: Fichier | C2: Nom du dossier dans les données acoustique du disque dur | K2: Lever_Soleil_Moy | L2: Lever_Soleil_Moyen
A3: Enr | B3: Enregistreur | C3: Nom du site d'enregistrement | K3: Coucher_Soleil_Moy | L3: Coucher_Soleil_Moyen
A4: EAA | B4: Enregistreur acoustique automatique | C4: Etiquette de l'enregistreur utilisée pour chaque site | K4: Longueur_Jour_Moy | L4: Longueur_Jour_Moyen
A5: Début | B5: Début | C5: Date de pose de l'enregistreur | K5: Alt(m) | L5: Altitude
A6: Fin | B6: Fin | C6: Date de fin d'enregistrement | K6: Commune | L6: Commune
A7: Lever_Soleil_Moy | B7: Lever_Soleil_Moyen | C7: Date du lever de soleil pour chaque site/enregistreur, en moyenne pour les jour ou ils ont été posé | K7: Hab | L7: Habitat
A8: Coucher_Soleil_Moy | B8: Coucher_Soleil_Moyen | C8: Date du coucher de soleil pour chaque site/enregistreur, en moyenne pour les jour ou ils ont été posé | K8: P_J_Moy(mm) | L8: Précipitation_Jour_Moyenne(mm)
A9: Longueur_Jour_Moy | B9: Longueur_Jour_Moyen | C9: Durée de longeur de jour pour chaque site/enregistreur, en moyenne pour les jour ou ils ont été posé | K9: P_J_Max(mm) | L9: Précipitation_Jour_Maximum(mm)
A10: Latitude | B10: Latitude | C10: Latitude pour chaque point GPS des enregistreurs | K10: T_Min_M(C°) | L10: Température_Minimal_Moyenne(C°)
A11: Longitude | B11: Longitude | C11: Longitude pour chaque point GPS des enregistreurs | K11: T_Max_M(C°) | L11: Température_Maximale_Moyenne(C°)
A12: Alt(m) | B12: Altitude | C12: Altitude pour chaque enregistreur | K12: Azi(°) | L12: Azimut(°)
A13: Commune | B13: Commune | C13: Commune ou un ensemble d'enregistreur en gradiant ont pu être posé | K13: Ori | L13: Orientation
... A26: D_R_P(m) | B26: Distance_Route_Principale(m) | C26: Distance direct entre l'enregistreur et la route principale faisant le tour de Tahiti, ou il y a le plus d'activité | K26: Nb_Day_2024 | L26: Nombre_Jour_2024
A27: D_M(m) | B27: Distance_Mer(m) | C27: Distance la plus courte à la mer
A28: D_B(m) | B28: Distance_batiment(m) | C28: Distance la plus courte à un batiment construit
A29: HSA(%) | B29: Hard_Surface_Area(%) | C29: Pourcentage de surface batie dans un rayon de 100m autour des enregistreurs, informe sur l'antropisation des millieux enregistrés
A30: Surface batie (m) | B30: Surface batie(m²) | C30: Surface batie mesurée par polygone à l'intérieur des cercles de 100 m de diamètre, permet d'obtenir le HSA
A31: Arb(%) | B31: Arbre(%) | C31: Couvert de végétation arborée visible autour des enregistreurs posés, effectuée par Emma Pilleboue lors de son stage et de la pose des EAA
A32: Arbu(%) | B32: Arbuste(%) | C32: Couvert de végétation arbustive visible autour des enregistreurs posés, effectuée par Emma Pilleboue lors de son stage et de la pose des EAA
A33: Her(%) | B33: Herbacée(%) | C33: Couvert de végétation herbacée visible autour des enregistreurs posés, effectuée par Emma Pilleboue lors de son stage et de la pose des EAA
A34: Ant(%) | B34: Anthropisque(%) | C34: Couvert de surface anthropique visible autour des enregistreurs, du batiments à la route bitumée
A35: N/E | B35: Natif/Exotique | C35: Proportion d'espèce Natif détectée sur les exotiques, lors de deux points écoutes effectuées à posteriori sur les données acoustique, on effectue la proportion conjointement sur la diversité totale détectée lors des deux points écoutes de 10 minutes
A36: S | B36: Species Richness | C36: Richesse total en espèce aviaire détecté lors de deux points écoutes effectuées à posteriori sur les données acoustique, on prend en compte la diversité maximal en combiant les deux points écoutes de 10 minutes
A37: Tps_Ana | B37: Temps_Analysée | C37: Nombre de minutes analysées pour obtenir les indices acoutiques
A38: Nb_Day_2024 | B38: Nombre_Jour_2024 | C38: Nombre de jour écoulée depuis le début de l'année 2024, avant la mise en place de l'enregistreur.
A39: Qualité,Commentaire | B39: Qualité,Commentaire

Sheet PO
A1: NAME_SPECIES | B1: LATIN_SPECIES | C1: STATUS | D1: DATE | E1: TIME_START | F1: TIME_STOP | G1: DAILY_TEXT_COMMENT_REM | H1: ENR | I1: COORD_LAT | J1: COORD_LON | K1: TRAFFIC | L1: RAIN | M1: WIND | N1: ACTIVITY | O1: EXTEND_NOISE | P1: MIC_NOISE
A2: Geopélie zébrée | B2: Geopelia striata | C2: Introduit | D2: 45350 | E2: 0.25 | F2: 0.25694444 | G2: No rain | H2: Ifremer_1 | I2: -17.80597 | J2: -149.29421
A3: Martin triste | B3: Acridotheres tristis | C3: Introduit | D3: 45350 | E3: 0.25 | F3: 0.25694444 | G3: No rain | H3: Ifremer_1 | I3: -17.80597 | J3: -149.29421
A4: Coq Banvika | B4: Gallus gallus | C4: Introduit | D4: 45350 | E4: 0.25 | F4: 0.25694444 | G4: No rain | H4: Ifremer_1 | I4: -17.80597 | J4: -149.29421
A5: Capucin donacole | B5: Lonchura castaneothorax | C5: Introduit | D5: 45350 | E5: 0.25 | F5: 0.25694444 | G5: No rain | H5: Ifremer_1 | I5: -17.80597 | J5: -149.29421
A6: Coq Banvika | B6: Gallus gallus | C6: Introduit | D6: 45351 | E6: 0.25 | F6: 0.25694444 | G6: 35.15 bruit chelou | H6: Ifremer_1 | I6: -17.80597 | J6: -149.29421 | K6: 1 | L6: 1 | M6: 1 | N6: 4 | O6: 1 | P6: 2
A7: Geopélie zébrée | B7: Geopelia striata | C7: Introduit | D7: 45351 | E7: 0.25 | F7: 0.25694444 | G7: 35.15 bruit chelou | H7: Ifremer_1 | I7: -17.80597 | J7: -149.29421 | K7: 1 | L7: 1 | M7: 1 | N7: 4 | O7: 1 | P7: 2
A8: Bulbul à ventre rouge | B8: Pycnonotus cafer | C8: Introduit | D8: 45351 | E8: 0.25 | F8: 0.25694444 | G8: 35.15 bruit chelou | H8: Ifremer_1 | I8: -17.80597 | J8: -149.29421 | K8: 1 | L8: 1 | M8: 1 | N8: 4 | O8: 1 | P8: 2
A9: Martin triste | B9: Acridotheres tristis | C9: Introduit | D9: 45351 | E9: 0.25 | F9: 0.25694444 | G9: 35.15 bruit chelou | H9: Ifremer_1 | I9: -17.80597 | J9: -149.29421 | K9: 1 | L9: 1 | M9: 1 | N9: 4 | O9: 1 | P9: 2
A10: Capucin donacole | B10: Lonchura castaneothorax | C10: Introduit | D10: 45351 | E10: 0.25 | F10: 0.25694444 | G10: 35.15 bruit chelou | H10: Ifremer_1 | I10: -17.80597 | J10: -149.29421 | K10: 1 | L10: 1 | M10: 1 | N10: 4 | O10: 1 | P10: 2
A11: Coq Banvika | B11: Gallus gallus | C11: Introduit | D11: 45395 | E11: 0.25 | F11: 0.25694444 | G11: No rain | H11: ILM_1 | I11: -17.73177 | J11: -149.57868
A12: Geopélie zébrée | B12: Geopelia striata | C12: Introduit | D12: 45395 | E12: 0.25 | F12: 0.25694444 | G12: No rain | H12: ILM_1 | I12: -17.73177 | J12: -149.57868
A13: Martin triste | B13: Acridotheres tristis | C13: Introduit | D13: 45395 | E13: 0.25 | F13: 0.25694444 | G13: No rain | H13: ILM_1 | I13: -17.73177 | J13: -149.57868
A14: Bulbul à ventre rouge | B14: Pycnonotus cafer | C14: Introduit | D14: 45395 | E14: 0.25 | F14: 0.25694444 | G14: No rain | H14: ILM_1 | I14: -17.73177 | J14: -149.57868
A15: Pigeon biset | B15: Columba livia | C15: Introduit | D15: 45395 | E15: 0.25 | F15: 0.25694444 | G15: No rain | H15: ILM_1 | I15: -17.73177 | J15: -149.57868
A16: Diamant à cinq couleur | B16: Neochmia temporalis | C16: Introduit | D16: 45395 | E16: 0.25 | F16: 0.25694444 | G16: No rain | H16: ILM_1 | I16: -17.73177 | J16: -149.57868
A17: Coq Banvika | B17: Gallus gallus | C17: Introduit | D17: 45396 | E17: 0.25 | F17: 0.25694444 | H17: ILM_1 | I17: -17.73177 | J17: -149.57868 | K17: 2 | L17: 1 | M17: 1 | N17: 5 | O17: 1 | P17: 1
A18: Geopélie zébrée | B18: Geopelia striata | C18: Introduit | D18: 45396 | E18: 0.25 | F18: 0.25694444 | H18: ILM_1 | I18: -17.73177 | J18: -149.57868 | K18: 2 | L18: 1 | M18: 1 | N18: 5 | O18: 1 | P18: 1
A19: Martin triste | B19: Acridotheres tristis | C19: Introduit | D19: 45396 | E19: 0.25 | F19: 0.25694444 | H19: ILM_1 | I19: -17.73177 | J19: -149.57868 | K19: 2 | L19: 1 | M19: 1 | N19: 5 | O19: 1 | P19: 1
A20: Bulbul à ventre rouge | B20: Pycnonotus cafer | C20: Introduit | D20: 45396 | E20: 0.25 | F20: 0.25694444 | H20: ILM_1 | I20: -17.73177 | J20: -149.57868 | K20: 2 | L20: 1 | M20: 1 | N20: 5 | O20: 1 | P20: 1
A21: Tangara à dos rouge | B21: Ramphocelus dimidiatus | C21: Introduit | D21: 45396 | E21: 0.25 | F21: 0.25694444 | H21: ILM_1 | I21: -17.73177 | J21: -149.57868 | K21: 2 | L21: 1 | M21: 1 | N21: 5 | O21: 1 | P21: 1
A22: Coq Banvika | B22: Gallus gallus | C22: Introduit | D22: 45395 | E22: 0.25 | F22: 0.25694444 | G22: No rain | H22: ILM_2 | I22: -17.73335 | J22: -149.57899
A23: Martin triste | B23: Acridotheres tristis | C23: Introduit | D23: 45395 | E23: 0.25 | F23: 0.25694444 | G23: No rain | H23: ILM_2 | I23: -17.73335 | J23: -149.57899
A24: Geopélie zébrée | B24: Geopelia striata | C24: Introduit | D24: 45395 | E24: 0.25 | F24: 0.25694444 | G24: No rain | H24: ILM_2 | I24: -17.73335 | J24: -149.57899
A25: Bulbul à ventre rouge | B25: Pycnonotus cafer | C25: Introduit | D25: 45395 | E25: 0.25 | F25: 0.25694444 | G25: No rain | H25: ILM_2 | I25: -17.73335 | J25: -149.57899
A26: Capucin donacole | B26: Lonchura castaneothorax | C26: Introduit | D26: 45395 | E26: 0.25 | F26: 0.25694444 | G26: No rain | H26: ILM_2 | I26: -17.73335 | J26: -149.57899
A27: Diamant à cinq couleur | B27: Neochmia temporalis | C27: Introduit | D27: 45395 | E27: 0.25 | F27: 0.25694444 | G27: No rain | H27: ILM_2 | I27: -17.73335 | J27: -149.57899
A28: Astrild ondulé | B28: Estrilda astrild | C28: Introduit | D28: 45395 | E28: 0.25 | F28: 0.25694444 | G28: No rain | H28: ILM_2 | I28: -17.73335 | J28: -149.57899
A29: Coq Banvika | B29: Gallus gallus | C29: Introduit | D29: 45396 | E29: 0.25 | F29: 0.25694444 | H29: ILM_2 | I29: -17.73335 | J29: -149.57899 | K29: 5 | L29: 1 | M29: 1 | N29: 4 | O29: 2 | P29: 5
A30: Martin triste | B30: Acridotheres tristis | C30: Introduit | D30: 45396 | E30: 0.25 | F30: 0.25694444 | H30: ILM_2 | I30: -17.73335 | J30: -149.57899 | K30: 5 | L30: 1 | M30: 1 | N30: 4 | O30: 2 | P30: 5
A31: Geopélie zébrée | B31: Geopelia striata | C31: Introduit | D31: 45396 | E31: 0.25 | F31: 0.25694444 | H31: ILM_2 | I31: -17.73335 | J31: -149.57899 | K31: 5 | L31: 1 | M31: 1 | N31: 4 | O31: 2 | P31: 5
A32: Bulbul à ventre rouge | B32: Pycnonotus cafer | C32: Introduit | D32: 45396 | E32: 0.25 | F32: 0.25694444 | H32: ILM_2 | I32: -17.73335 | J32: -149.57899 | K32: 5 | L32: 1 | M32: 1 | N32: 4 | O32: 2 | P32: 5
A33: Capucin donacole | B33: Lonchura castaneothorax | C33: Introduit | D33: 45396 | E33: 0.25 | F33: 0.25694444 | H33: ILM_2 | I33: -17.73335 | J33: -149.57899 | K33: 5 | L33: 1 | M33: 1 | N33: 4 | O33: 2 | P33: 5
A34: Zosterops à dos gris | B34: Zosterops lateralis | C34: Introduit | D34: 45396 | E34: 0.25 | F34: 0.25694444 | H34: ILM_2 | I34: -17.73335 | J34: -149.57899 | K34: 5 | L34: 1 | M34: 1 | N34: 4 | O34: 2 | P34: 5
A35: Coq Banvika | B35: Gallus gallus | C35: Introduit | D35: 45395 | E35: 0.25 | F35: 0.25694444 | G35: No rain | H35: ILM_3 | I35: -17.73234 | J35: -149.57782
A36: Bulbul à ventre rouge | B36: Pycnonotus cafer | C36: Introduit | D36: 45395 | E36: 0.25 | F36: 0.25694444 | G36: No rain | H36: ILM_3 | I36: -17.73234 | J36: -149.57782
A37: Martin triste | B37: Acridotheres tristis | C37: Introduit | D37: 45395 | E37: 0.25 | F37: 0.25694444 | G37: No rain | H37: ILM_3 | I37: -17.73234 | J37: -149.57782
A38: Capucin donacole | B38: Lonchura castaneothorax | C38: Introduit | D38: 45395 | E38: 0.25 | F38: 0.25694444 | G38: No rain | H38: ILM_3 | I38: -17.73234 | J38: -149.57782
A39: Geopélie zébrée | B39: Geopelia striata | C39: Introduit | D39: 45395 | E39: 0.25 | F39: 0.25694444 | G39: No rain | H39: ILM_3 | I39: -17.73234 | J39: -149.57782
A40: Bulbul à ventre rouge | B40: Pycnonotus cafer | C40: Introduit | D40: 45396 | E40: 0.25 | F40: 0.25694444 | H40: ILM_3 | I40: -17.73234 | J40: -149.57782 | K40: 3 | L40: 1 | M40: 1 | N40: 5 | O40: 4 | P40: 1
...

Sheet Feuil2
A1: NAME_SPECIES | B1: LATIN_SPECIES | C1: STATUS | D1: ENR | I1: ENR | J1: NAT | K1: INT | N1: 1_ID | O1: 9_Description_habita
A2: Nom espèce | B2: Nom scientifique | C2: Status | D2: Enregistreur | I2: Enregistreur | J2: Natif | K2: Introduit | N2: PI_Embouchure_1 | O2: 10% pelouse, 50% arbre, 40% arbustes,5% construction anthropique | Q2: For Azimut :
A3: Bulbul à ventre rouge | B3: Pycnonotus cafer | C3: Introduit | D3: Ifremer_1 | I3: Ifremer_1 | J3: =COUNTIF(C3:C7,"Natif") -> 0 | K3: =COUNTIF(C3:C7,"Introduit") -> 5 | N3: PI_Embouchure_2 | O3: 50% herbacés, 50% arbustes, 50% arbres | Q3: Tahiti Nui | R3: -17.6333308 | S3: -149.4499982
A4: Capucin donacole | B4: Lonchura castaneothorax | C4: Introduit | D4: Ifremer_1 | I4: ILM_1 | J4: =COUNTIF(C8:C14,"Natif") -> 0 | K4: =COUNTIF(C8:C14,"Introduit") -> 7 | N4: PI_Embouchure_3 | O4: 40% herbacés, 50% arbustes, 60% arbres | Q4: Tahiti Iti | R4: -17.808003 | S4: -149.209419
A5: Coq Banvika | B5: Gallus gallus | C5: Introduit | D5: Ifremer_1 | I5: ILM_2 | J5: =COUNTIF(C15:C22,"Natif") -> 0 | K5: =COUNTIF(C15:C22,"Introduit") -> 8 | N5: PI_Embouchure_4 | O5: 40% herbacés, 60% arbustes,70% arbred
A6: Geopélie zébrée | B6: Geopelia striata | C6: Introduit | D6: Ifremer_1 | I6: ILM_3 | J6: =COUNTIF(C23:C28,"Natif") -> 0 | K6: =COUNTIF(C23:C28,"Introduit") -> 6 | N6: PI_Belvedere_2 | O6: 50% strateherbacés haute, 60% arbustes, 40% arbres
A7: Martin triste | B7: Acridotheres tristis | C7: Introduit | D7: Ifremer_1 | I7: Jardin_Eau_1 | J7: =COUNTIF(C29:C35,"Natif") -> 1 | K7: =COUNTIF(C29:C35,"Introduit") -> 6 | N7: PI_Belvedere_1 | O7: 60% haute herbacées haute, 40% arbuste, 20% arbres
A8: Bulbul à ventre rouge | B8: Pycnonotus cafer | C8: Introduit | D8: ILM_1 | I8: Jardin_Eau_2 | J8: =COUNTIF(C36:C43,"Natif") -> 1 | K8: =COUNTIF(C36:C43,"Introduit") -> 7 | N8: PI_Belvedere_3 | O8: 60% herbacé, 60% arbustes, 60% arbres
A9: Coq Banvika | B9: Gallus gallus | C9: Introduit | D9: ILM_1 | I9: Jardin_Eau_3 | J9: =COUNTIF(C44:C48,"Natif") -> 0 | K9: =COUNTIF(C44:C48,"Introduit") -> 5 | N9: PI_Belvedere_4 | O9: 30% chemin terre/gravier, 70% herbacés, 40% arbustes, 15% arbres
A10: Diamant à cinq couleur | B10: Neochmia temporalis | C10: Introduit | D10: ILM_1 | I10: Jardin_Eau_4 | J10: =COUNTIF(C49:C54,"Natif") -> 1 | K10: =COUNTIF(C49:C54,"Introduit") -> 5 | N10: PI_Belvedere_5 | O10: Prairies maj
A11: Geopélie zébrée | B11: Geopelia striata | C11: Introduit | D11: ILM_1 | I11: Jardin_Eau_5 | J11: =COUNTIF(C55:C59,"Natif") -> 0 | K11: =COUNTIF(C55:C59,"Introduit") -> 5 | N11: PI_Belvedere_6 | O11: Prairie / paturage
A12: Martin triste | B12: Acridotheres tristis | C12: Introduit | D12: ILM_1 | I12: Marae_1 | J12: =COUNTIF(C60:C66,"Natif") -> 0 | K12: =COUNTIF(C60:C66,"Introduit") -> 7 | N12: PI_Belvedere_7 | O12: Prairie / paturage
A13: Pigeon biset | B13: Columba livia | C13: Introduit | D13: ILM_1 | I13: Marae_2 | J13: =COUNTIF(C67:C75,"Natif") -> 2 | K13: =COUNTIF(C67:C75,"Introduit") -> 7 | N13: PI_Belvedere_8 | O13: Prairie
A14: Tangara à dos rouge | B14: Ramphocelus dimidiatus | C14: Introduit | D14: ILM_1 | I14: Marae_3 | J14: =COUNTIF(C76:C79,"Natif") -> 0 | K14: =COUNTIF(C76:C79,"Introduit") -> 4 | N14: PI_Belvedere_9 | O14: Foret / prairie
A15: Astrild ondulé | B15: Estrilda astrild | C15: Introduit | D15: ILM_2 | I15: Marae_4 | J15: =COUNTIF(C80:C85,"Natif") -> 0 | K15: =COUNTIF(C80:C85,"Introduit") -> 6 | N15: PI_Puunui_1
A16: Bulbul à ventre rouge | B16: Pycnonotus cafer | C16: Introduit | D16: ILM_2 | I16: OBelvedere_1 | J16: =COUNTIF(C86:C91,"Natif") -> 1 | K16: =COUNTIF(C86:C91,"Introduit") -> 5 | N16: PI_Puunui_2 | O16: Prairie / champ
